<?xml version="1.0"?>
<robot xmlns:xacro="http://www.ros.org/wiki/xacro">

    <xacro:property name="base_length" value="1.0" />
    <xacro:property name="base_radius" value="0.4" />
    <!-- <xacro:property name="base_width" value="0.4" /> -->
    <!-- <xacro:property name="base_height" value="0.2" /> -->
    <!-- <xacro:property name="wheel_radius" value="0.1" /> -->
    <!-- <xacro:property name="wheel_length" value="0.05" /> -->

    <!-- BASE LINK -->
    <link name="base_link"></link>

    <!-- CHASSIS LINK -->
    <joint name="chassis_joint" type="fixed">
        <parent link="base_link" />
        <child link="chassis" />
        <origin xyz="0 0 0" rpy="0 ${pi/2} 0" />
    </joint>

    <link name="chassis">
        <visual>
            <origin xyz="0 0 0" rpy="0 0 0" />
            <geometry>
                <cylinder radius="0.06" length="1.0" />
            </geometry>
            <material name="white" />
        </visual>
    </link>

    <!-- PROPELLER LINK -->
    <joint name="propeller_joint" type="continuous">
        <parent link="base_link" />
        <child link="propeller" />
        <origin xyz="-0.51 0 0" rpy="0 ${pi/2} 0" />
        <axis xyz="0 0 1" />
    </joint>

    <link name="propeller">
        <visual>
            <geometry>
                <box size="0.2 0.02 0.01" />
            </geometry>
            <material name="orange" />
        </visual>
        <collision>
            <geometry>
                <box size="0.2 0.02 0.01" />
            </geometry>
        </collision>
        <inertial>
            <mass value="0.1" />
            <inertia ixx="0.001" ixy="0" ixz="0"
                iyy="0.001" iyz="0"
                izz="0.001" />
        </inertial>
    </link>

</robot>